Workbook

Sheet Respuestas
A1: Marca temporal | B1: Dirección de correo electrónico | C1: Edad | D1: Género | E1: Nivel educativo | F1: Ocupación | G1: 1 | H1: 2 | I1: 3 | J1: 4 | K1: 5 | L1: 6 | M1: 7 | N1: 8 | O1: 9 | P1: 10 | Q1: ¿Cuáles son los principales aspectos positivos que resalta del producto software? | R1: ¿Qué aspectos son susceptibles de ser mejorados en el producto software? | S1: ¿Qué característica(s) sería(n) importante(s) incluir en el producto software para mejorar la facilidad de uso?
A2: 46119.41 | B2: ppabon@umariana.edu.co | C2: 38 | D2: Masculino | E2: Posgrado | F2: Empleado | G2: Totalmente de acuerdo | H2: Neutro | I2: Neutro | J2: De acuerdo | K2: Totalmente de acuerdo | L2: Neutro | M2: De acuerdo | N2: Totalmente en desacuerdo | O2: Totalmente de acuerdo | P2: De acuerdo | Q2: el poder visualizar los registros en tiempo real y que estos datos sean tanto numéricos como gráficos; los párrafos de información son precisos y puntuales | R2: la pagina de inicio no tiene una bienvenida y de que trata el software, no hay un instructivo para ser manejado de manera independiente. | S2: * un icono de aprende a usarlo (con ejemplo puntual de como se usa el software). * contextualizar los contaminantes - tienen un encabezado de ¿Por qué es importante? pero que es o que tamaño tiene el contaminante no se aprecia en el software. * en lo posible incluir una representación visual de los diferentes contaminantes y una comparación de tamaño con algo como un cabello humano. * algún apartado de "acerca de" y de requisitos necesarios.
A3: 46119.434 | B3: jenjimenezp223@umariana.edu.co | C3: 35 | D3: Femenino | E3: Posgrado | F3: Empleado | G3: De acuerdo | H3: Totalmente en desacuerdo | I3: Totalmente de acuerdo | J3: En desacuerdo | K3: De acuerdo | L3: Totalmente en desacuerdo | M3: Neutro | N3: Totalmente en desacuerdo | O3: De acuerdo | P3: En desacuerdo | Q3: Los gráficos son amigables con el usuario, buenos colores, que permita descargar los datos historias | R3: Que al iniciar sesión diga explícitamente que se puede iniciar con el correo de umariana. Especificar que el limite hace referencia al nivel de advertencia, explicar los diferentes niveles que menciona la normativa | S3: Que se pueda modificar los ejes, hacer zoom o alejar para ver los datos historia directamente en el software sin tener que descargar los datos.
A4: 46119.443 | B4: rojeda@umariana.edu.co | C4: 43 | D4: Femenino | E4: Posgrado | F4: Empleado | G4: Neutro | H4: Totalmente en desacuerdo | I4: Totalmente de acuerdo | J4: Totalmente en desacuerdo | K4: Totalmente de acuerdo | L4: En desacuerdo | M4: Totalmente de acuerdo | N4: Totalmente en desacuerdo | O4: De acuerdo | P4: Totalmente en desacuerdo | Q4: es fácil de usar, la medición en tiempo real | R4: en el inicio dice que son 6 colores pero aparecen 4. Mejorar el rango de la presentacion de datos en tiempo real, es decir si vemos pm 2.5, la ghrafica hasta 160 es muy grande y no se puede distinguir el valor de 2.5 graficamente. Sugiero que los textos de la información de la importancia de las mediciones ambientales sean más enfocados en la prevención. poner un tip de la detección de algun parámetro en forma propositiva. | S4: hacer la presentacion de datos en tiempo real con graficas mas ajustadas y que se pueda ver mas tiempo
A5: 46119.457 | B5: fmaffla@yahoo.com.ar | C5: 49 | D5: Masculino | E5: Posgrado | F5: Empleado | G5: De acuerdo | H5: Totalmente en desacuerdo | I5: Totalmente de acuerdo | J5: Totalmente en desacuerdo | K5: De acuerdo | L5: Totalmente en desacuerdo | M5: De acuerdo | N5: Totalmente en desacuerdo | O5: De acuerdo | P5: Totalmente en desacuerdo | Q5: el tipo de resultados y su temporalidad | R5: información acerca de donde se realiza la medición en caso de que sea una estación fija, datos de calibración de sensores para tener certeza de que la información es de buena calidad. | S5: mapa de ubicación, en caso de estación fija
A6: 46119.465 | B6: glucardenas@umariana.edu.co | C6: 53 | D6: Femenino | E6: Posgrado | F6: Empleado | G6: Totalmente de acuerdo | H6: Totalmente en desacuerdo | I6: Totalmente de acuerdo | J6: De acuerdo | K6: Totalmente de acuerdo | L6: Totalmente en desacuerdo | M6: Totalmente de acuerdo | N6: Totalmente en desacuerdo | O6: Totalmente de acuerdo | P6: De acuerdo | Q6: Bonito, amigable, util | R6: En la pestaña de niveles mensuales sería importante que al hacer un click en el día se dirigiera a la pesataña descatar datos de eat manera es más fácil para el usuario. La pestaña de descargar datos se podría eliminar de la parte superior. En la pestaña de niveles mensuales donde aparecen los meses y días colocar la tabla de que significa este color a un lado para no tener que bajar Los niveles de tiempo en los niveles mensuales deben ser precisamente la info de el último mes en la visualización no por segundos, no es necesario | S6: La pantalla de inicio debe dar una idea de lo que hace el programa. Cuando entre pensé que solo media pm2,5 y monóxido porque es lo que está ahí pero mide muchas más cosas. Por ello siento que no se debería cambiar la información a la explicación de lo que es cada uno de los parámetros
A7: 46119.468 | B7: smadronero@umariana.edu.co | C7: 46 | D7: Femenino | E7: Posgrado | F7: Empleado | G7: De acuerdo | H7: Totalmente en desacuerdo | I7: Totalmente de acuerdo | J7: Totalmente en desacuerdo | K7: Totalmente de acuerdo | L7: Totalmente en desacuerdo | M7: Totalmente de acuerdo | N7: Totalmente en desacuerdo | O7: Totalmente de acuerdo | P7: Totalmente en desacuerdo | Q7: el sofware es bastante intuitivo y facil de manejar | R7: mejoraria algunos aspectos de la presentacion como por ejemplo que la informacion que se mira inicialmente no se presente en segundos sino por horas, podria ser mas facil darle click en la fecha y que me redijira a la descarga especifica de los datos que se obtuvieron en la fecha señalada. | S7: Las mencionadas anteriormente.
A8: 46121.352 | B8: terocanchala123@umariana.edu.co | C8: 39 | D8: Femenino | E8: Posgrado | F8: Empleado | G8: De acuerdo | H8: En desacuerdo | I8: De acuerdo | J8: Totalmente en desacuerdo | K8: De acuerdo | L8: Totalmente en desacuerdo | M8: Totalmente de acuerdo | N8: Totalmente en desacuerdo | O8: De acuerdo | P8: Totalmente en desacuerdo | Q8: Resalto la visualización de la información tanto gráfica como de visualización de datos disponibles para exportar | R8: Que en los gráficos se pueda visualizar el histórico guardado en él con un periodo de tiempo más amplio que el disponible. Facilitar la descarga de los gráficos, no solo permitir la descarga de los datos En la visualización de los gráficos poder hacer zoom en algunas partes. Poder establecer el limite máximo permisible por parte del usuario, ya es que esta varia teniendo en cuenta si se requiere realizar un análisis horario, semanal, mensual etc, o si se piensa para otros paises estos limites establecidos por normativa podrían cambiar. | S8: Incluir un protocolo tipo video corto al inicio del software, para que el primer encuentro con el software sea más fácil. Aunque se resalta que el software es intuitivo, lo cual hace fácil la navegación.
A9: 46122.469 | B9: jcnarvaez@umariana.edu.co | C9: 49 | D9: Masculino | E9: Posgrado | F9: Empleado | G9: De acuerdo | H9: Neutro | I9: Neutro | J9: De acuerdo | K9: De acuerdo | L9: En desacuerdo | M9: De acuerdo | N9: En desacuerdo | O9: Neutro | P9: Neutro | Q9: La apariencia visual de los parámetros | R9: La presentación de información meteorológica es muy importante y no únicamente de los datos en series de tiempo. Se deberían extender las series de tiempo a mas de una hora para poder ver los contrastes en un día o en el periodo que uno requiera analizar | S9: Un bot que permita reconocer cada componente de la visualización, su funcionamiento y cual es el alcance de la información suministrada de a cuerdo a cada parámetro o a un conjunto de ellos.
A10: 46122.508 | B10: dgguerrero@umariana.edu.co | C10: 38 | D10: Femenino | E10: Posgrado | F10: Empleado | G10: De acuerdo | H10: Totalmente en desacuerdo | I10: Totalmente de acuerdo | J10: Neutro | K10: Totalmente de acuerdo | L10: En desacuerdo | M10: De acuerdo | N10: Totalmente en desacuerdo | O10: Totalmente de acuerdo | P10: En desacuerdo | Q10: Que es amigable y fácil de entender | R10: La descarga de datos diarios | S10: Talvez explicar un poco mas las variables que mide la estación
A11: 46122.526 | B11: anmacadena223@umariana.edu.co | C11: 20 | D11: Femenino | E11: Universidad (pregrado) | F11: Estudiante | G11: Totalmente de acuerdo | H11: Neutro | I11: De acuerdo | J11: Totalmente en desacuerdo | K11: Totalmente de acuerdo | L11: En desacuerdo | M11: De acuerdo | N11: Totalmente en desacuerdo | O11: Totalmente de acuerdo | P11: Totalmente en desacuerdo | Q11: Es muy intuitivo y fácil de manejar | R11: A mi percepción ninguno | S11: A mi parecer ninguna
A12: 46122.526 | B12: kajupaz223@umariana.edu.co | C12: 20 | D12: Femenino | E12: Universidad (pregrado) | F12: Estudiante | G12: Totalmente de acuerdo | H12: Neutro | I12: Neutro | J12: En desacuerdo | K12: Totalmente de acuerdo | L12: Totalmente en desacuerdo | M12: Totalmente de acuerdo | N12: Totalmente en desacuerdo | O12: Totalmente de acuerdo | P12: Totalmente en desacuerdo | Q12: Practico | R12: Ninguna | S12: Ninguna
A13: 46122.571 | B13: karpedroza225@umariana.edu.co | C13: 17 | D13: Femenino | E13: Universidad (pregrado) | F13: Estudiante | G13: Totalmente de acuerdo | H13: Totalmente en desacuerdo | I13: Totalmente en desacuerdo | J13: Totalmente en desacuerdo | K13: Totalmente de acuerdo | L13: En desacuerdo | M13: Totalmente de acuerdo | N13: Totalmente en desacuerdo | O13: Totalmente de acuerdo | P13: Neutro | Q13: Qué es muy difícil de utilizar | R13: Puede ser la presentación el aparato | S13: Pues para mí está muy sencillo de utilizar
A14: 46122.571 | B14: wilportilla225@umariana.edu.co | C14: 19 | D14: Masculino | E14: Universidad (pregrado) | F14: Estudiante | G14: Totalmente de acuerdo | H14: Neutro | I14: Totalmente en desacuerdo | J14: Totalmente en desacuerdo | K14: Totalmente de acuerdo | L14: Totalmente en desacuerdo | M14: Totalmente de acuerdo | N14: Totalmente en desacuerdo | O14: Totalmente de acuerdo | P14: Totalmente en desacuerdo
A15: 46122.572 | B15: dansapuyes225@umariana.edu.co | C15: 18 | D15: Femenino | E15: Universidad (pregrado) | F15: Estudiante | G15: Totalmente en desacuerdo | H15: En desacuerdo | I15: Totalmente en desacuerdo | J15: Totalmente en desacuerdo | K15: Totalmente en desacuerdo | L15: En desacuerdo | M15: Totalmente en desacuerdo | N15: En desacuerdo | O15: Totalmente en desacuerdo | P15: En desacuerdo
A16: 46122.572 | B16: sheguzman225@umariana.edu.co | C16: 18 | D16: Femenino | E16: Universidad (pregrado) | F16: Estudiante | G16: Totalmente de acuerdo | H16: Neutro | I16: De acuerdo | J16: De acuerdo | K16: De acuerdo | L16: En desacuerdo | M16: Neutro | N16: De acuerdo | O16: Totalmente de acuerdo | P16: Totalmente en desacuerdo | Q16: Nos ayudaría a tener más claro los niveles de contaminantes | R16: Al momento de descargar los niveles mensuales y abrir el documento, debería estar ya organizado en tabla para no perder tiempo | S16: Ninguna
A17: 46122.573 | B17: brypastas225@umariana.edu.co | C17: 22 | D17: Masculino | E17: Universidad (pregrado) | F17: Estudiante | G17: Totalmente en desacuerdo | H17: En desacuerdo | I17: Totalmente en desacuerdo | J17: En desacuerdo | K17: Totalmente en desacuerdo | L17: Totalmente en desacuerdo | M17: Totalmente en desacuerdo | N17: Totalmente en desacuerdo | O17: Totalmente en desacuerdo | P17: Totalmente en desacuerdo | Q17: Es muy fácil de usar y comprender | R17: Ninguno | S17: Ninguno
A18: 46122.586 | B18: darosero225@umariana.edu.co | C18: 18 | D18: Masculino | E18: Universidad (pregrado) | F18: Estudiante | G18: Neutro | H18: En desacuerdo | I18: Totalmente en desacuerdo | J18: En desacuerdo | K18: De acuerdo | L18: Neutro | M18: De acuerdo | N18: Neutro | O18: De acuerdo | P18: Totalmente de acuerdo | Q18: La interfaz, pues que es muy fácil de manejar | R18: Corrección de errores o fallos | S18: Tutoriales o guias dentro de la aplicación
A19: 46122.685 | B19: panirosero223@umariana.edu.co | C19: 20 | D19: Femenino | E19: Universidad (pregrado) | F19: Estudiante | G19: Totalmente en desacuerdo | H19: En desacuerdo | I19: Neutro | J19: En desacuerdo | K19: Totalmente en desacuerdo | L19: En desacuerdo | M19: Totalmente en desacuerdo | N19: En desacuerdo | O19: Totalmente en desacuerdo | P19: En desacuerdo | Q19: muy organizado, la información se muestra clara, se puede descargar datos con facilidad y muy claros. | R19: En mi opinión, siento que el software está muy completo y listo para aplicarse | S19: Ningunas, el uso de software es muy facil para manejar
A20: 46122.687 | B20: latapatino223@umariana.edu.co | C20: 23 | D20: Femenino | E20: Secundaria | F20: Estudiante | G20: Totalmente de acuerdo | H20: Totalmente en desacuerdo | I20: Totalmente en desacuerdo | J20: Totalmente en desacuerdo | K20: Totalmente de acuerdo | L20: Totalmente en desacuerdo | M20: Totalmente de acuerdo | N20: Totalmente en desacuerdo | O20: Totalmente de acuerdo | P20: Totalmente en desacuerdo | Q20: La organización del programa y su función dónde se ve claramente los estudios que refleja el arduino | R20: Que al inicio se muestre también la tabla de resultados | S20: Ya que se den más prácticas del mismo en el salón de clases para que se dé a conocer
A21: 46122.697 | B21: nirubio@umariana.edu.co | C21: 27 | D21: Femenino | E21: Posgrado | F21: Empleado | G21: Totalmente de acuerdo | H21: Totalmente en desacuerdo | I21: En desacuerdo | J21: Totalmente en desacuerdo | K21: Totalmente de acuerdo | L21: Totalmente en desacuerdo | M21: Totalmente de acuerdo | N21: Totalmente en desacuerdo | O21: Totalmente de acuerdo | P21: Totalmente en desacuerdo | Q21: Es un software fácil de entender, muy gráfico y presenta los datos en tiempo real y de manera organizada.
A22: 46122.699 | B22: jimjbasantet124@umariana.edu.co | C22: 19 | D22: Masculino | E22: Universidad (pregrado) | F22: Estudiante | G22: De acuerdo | H22: En desacuerdo | I22: De acuerdo | J22: De acuerdo | K22: Neutro | L22: Neutro | M22: De acuerdo | N22: En desacuerdo | O22: De acuerdo | P22: Totalmente en desacuerdo | Q22: Facil manejo de la plataforma, datos actualizados y visibilidad de los datos | R22: Mejor la decarga y visualizacion de los datos en excel, ajustar mejor el modelo para tener una menor desviacion entre los datos | S22: Video tutorial.
A23: 46122.7 | B23: cridcastellanoc124@umariana.edu.co | C23: 23 | D23: Masculino | E23: Educación técnica o tecnológica | F23: Estudiante | G23: De acuerdo | H23: En desacuerdo | I23: De acuerdo | J23: De acuerdo | K23: Neutro | L23: Neutro | M23: Totalmente de acuerdo | N23: Totalmente en desacuerdo | O23: Neutro | P23: Totalmente en desacuerdo | Q23: Fácil anejo de la plataforma , datos actualizados y visibilidad de lo datos | R23: La visualización y descarga en Excel ajustar el modelo de datos | S23: Video tutorial en que expliques cómo se el software
A24: 46122.708 | B24: laenriquez222@umariana.edu.co | C24: 28 | D24: Femenino | E24: Universidad (pregrado) | F24: Estudiante | G24: Totalmente de acuerdo | H24: En desacuerdo | I24: Totalmente de acuerdo | J24: Totalmente en desacuerdo | K24: Totalmente de acuerdo | L24: Totalmente en desacuerdo | M24: Totalmente de acuerdo | N24: Totalmente en desacuerdo | O24: Totalmente de acuerdo | P24: Totalmente en desacuerdo | Q24: La facilidad con que se pueden medir variables y la descarga de datos | R24: Una imagen más gráfica de los datos | S24: Imágenes que permitan entender mejor los datos.
A25: 46122.708 | B25: apdurango222@umariana.edu.co | C25: 25 | D25: Femenino | E25: Universidad (pregrado) | F25: Estudiante | G25: Totalmente de acuerdo | H25: En desacuerdo | I25: En desacuerdo | J25: En desacuerdo | K25: Totalmente de acuerdo | L25: En desacuerdo | M25: De acuerdo | N25: Totalmente en desacuerdo | O25: Totalmente de acuerdo | P25: Totalmente en desacuerdo | Q25: La facilidad con la que se puede descargar la información | R25: Una imagen más gráfica de los datos obtenidos | S25: Imágenes que permitan entender mejor los valores obtenidos en cada variable.
A26: 46125.405 | B26: maiscabrera123@umariana.edu.co | C26: 19 | D26: Femenino | E26: Universidad (pregrado) | F26: Estudiante | G26: Totalmente de acuerdo | H26: Neutro | I26: Neutro | J26: Totalmente de acuerdo | K26: Totalmente de acuerdo | L26: Totalmente en desacuerdo | M26: Totalmente de acuerdo | N26: Totalmente en desacuerdo | O26: Neutro | P26: En desacuerdo | Q26: Tiene bastantes funcionalidades que sirven | R26: Considero que está bien pero hay muchas ventanas, necesitaría una explicación más detallada de cómo se usa y adquiere los datos, incluso de cómo los puedo generar. quizás sería bueno que haya una parte donde sea un tipo de manual donde se explique
A27: 46125.405 | B27: mariacvega123@umariana.edu.co | C27: 20 | D27: Femenino | E27: Universidad (pregrado) | F27: Estudiante | G27: Totalmente de acuerdo | H27: Totalmente en desacuerdo | I27: Totalmente de acuerdo | J27: Neutro | K27: Totalmente de acuerdo | L27: Totalmente en desacuerdo | M27: Neutro | N27: Totalmente en desacuerdo | O27: Totalmente de acuerdo | P27: Neutro | Q27: Qué es fácil de manejar, y da las variables que se necesita | R27: Una guía de manejo para las personas que son nuevas en el tema | S27: Todo está bien, no se debe incluir nada
A28: 46125.406 | B28: juliaiinac.inca221@umariana.edu.co | C28: 23 | D28: Femenino | E28: Universidad (pregrado) | F28: Estudiante | G28: De acuerdo | H28: En desacuerdo | I28: Neutro | J28: En desacuerdo | K28: Totalmente de acuerdo | L28: En desacuerdo | M28: Totalmente de acuerdo | N28: En desacuerdo | O28: Totalmente de acuerdo | P28: Neutro | Q28: Es muy complementario para la toma de decisiones con respecto a la contaminación del aire | R28: Que cada persona pueda tomar los datos directamente en un punto especifico y que que se pueda monitorear el micro controlador
A29: 46125.407 | B29: camamantilla123@umariana.edu.co | C29: 21 | D29: Masculino | E29: Universidad (pregrado) | F29: Estudiante | G29: Totalmente en desacuerdo | H29: Totalmente de acuerdo | I29: En desacuerdo | J29: En desacuerdo | K29: En desacuerdo | L29: Totalmente de acuerdo | M29: Totalmente en desacuerdo | N29: Totalmente de acuerdo | O29: En desacuerdo | P29: En desacuerdo | Q29: El apoyo al aire | R29: La alimentacion del arduino y q no tenga q estar usandose con datos | S29: Una caja o algo para proteger al arduino por q así puede ser muy sensible a golpes
A30: 46125.407 | B30: ansovargas123@umariana.edu.co | C30: 20 | D30: Femenino | E30: Universidad (pregrado) | F30: Estudiante | G30: Totalmente de acuerdo | H30: En desacuerdo | I30: De acuerdo | J30: En desacuerdo | K30: Totalmente de acuerdo | L30: Totalmente en desacuerdo | M30: De acuerdo | N30: En desacuerdo | O30: De acuerdo | P30: Neutro | Q30: Es fácil de entender y amable con el usuario | R30: Se necesitarían más datos de diferentes estaciones para que los datos sean más confiables a una escala un poco mayor, pero si se quiere medir datos en un espacio más reducido está bastante bien | S30: La ubicación de donde se toman los datos
A31: 46125.407 | B31: Kalisierra123@umariana.edu.co | C31: 19 | D31: Femenino | E31: Universidad (pregrado) | F31: Estudiante | G31: Totalmente de acuerdo | H31: En desacuerdo | I31: En desacuerdo | J31: En desacuerdo | K31: Totalmente de acuerdo | L31: En desacuerdo | M31: Totalmente de acuerdo | N31: En desacuerdo | O31: Totalmente de acuerdo | P31: Neutro | Q31: Algo bueno, innovador para la universidad Mariana | R31: Esta super bien | S31: Sería que al momento de descargar los pdf que genera aparezca gráficas para tener una visualización mas clara
A32: 46125.407 | B32: katherinch.jaramillo@umariana.edu.co | C32: 22 | D32: Femenino | E32: Universidad (pregrado) | F32: Estudiante | G32: De acuerdo | H32: De acuerdo | I32: Neutro | J32: Totalmente de acuerdo | K32: De acuerdo | L32: Neutro | M32: Totalmente de acuerdo | N32: Neutro | O32: Neutro | P32: Neutro | Q32: Poder obtener datos reales | R32: Un poco más específico en las gráficas y facilidad de uso | S32: Interfaz simple, navegación clara, información resumida, carga rápida y opciones de personalización para el usuario.
A33: 46125.407 | B33: ivmaperenguez123@umariana.edu.co | C33: 21 | D33: Masculino | E33: Universidad (pregrado) | F33: Estudiante | G33: Totalmente en desacuerdo | H33: Totalmente en desacuerdo | I33: Totalmente en desacuerdo | J33: Totalmente en desacuerdo | K33: Totalmente en desacuerdo | L33: Totalmente en desacuerdo | M33: Totalmente en desacuerdo | N33: Totalmente en desacuerdo | O33: Totalmente en desacuerdo | P33: Totalmente en desacuerdo | Q33: Los datos son claros, al momento de visualizarlos se puede identificarlos de manera adecuada y ordenada, además su sistema operativo en muy entendible | R33: Está bien estructurado | S33: Un lenguaje hablado, como estilo servidor de siri, esto sería muy interesante
A34: 46125.408 | B34: maparosales123@umariana.edu.co | C34: 21 | D34: Femenino | E34: Universidad (pregrado) | F34: Estudiante | G34: Totalmente de acuerdo | H34: En desacuerdo | I34: Totalmente en desacuerdo | J34: Totalmente en desacuerdo | K34: Totalmente de acuerdo | L34: Totalmente en desacuerdo | M34: Totalmente de acuerdo | N34: Totalmente en desacuerdo | O34: Totalmente de acuerdo | P34: Totalmente en desacuerdo | Q34: Me gusta la facilidad de interacción en la plataforma, se ajusta a las necesidades del análisis de datos en estudios | R34: Que sea accesible para más personas | S34: Que se tenga en cuenta un posible prototipo el cual se coloque en mercado y ayude a otros lugares a conocer acerca de la calidad de aire y generar datos
A35: 46125.408 | B35: alexandra.piaguajeor212@umariana.edu.co | C35: 21 | D35: Femenino | E35: Universidad (pregrado) | F35: Estudiante | G35: Totalmente en desacuerdo | H35: Totalmente en desacuerdo | I35: En desacuerdo | J35: Totalmente en desacuerdo | K35: Totalmente en desacuerdo | L35: Totalmente en desacuerdo | M35: Totalmente en desacuerdo | N35: En desacuerdo | O35: Totalmente en desacuerdo | P35: En desacuerdo | Q35: la facilidad de uso. Un buen software entenderlo y manejarlo sin necesidad de mucha explicación o capacitación. | R35: rendimiento, logrando que el software sea más rápido, consuma menos recursos y no se bloquee o se vuelva lento. | S35: También es clave incluir guías o tutoriales dentro del sistema, como instrucciones paso a paso, ayudas emergentes o asistentes que orienten al usuario al inicio.
A36: 46125.408 | B36: brdagarcia123@umariana.edu.co | C36: 25 | D36: Masculino | E36: Universidad (pregrado) | F36: Estudiante | G36: De acuerdo | H36: Neutro | I36: Neutro | J36: De acuerdo | K36: Neutro | L36: En desacuerdo | M36: Totalmente de acuerdo | N36: En desacuerdo | O36: De acuerdo | P36: De acuerdo | Q36: El software es muy práctico y da variables muy interesantes para medir con respecto abla calidad del aire | R36: Que presente más variables como SO2, NOx y O3 | S36: Ninguno es práctico y entendible
A37: 46125.408 | B37: judichachinoy123@umariana.edu.co | C37: 25 | D37: Masculino | E37: Secundaria | F37: Estudiante | G37: Totalmente de acuerdo | H37: En desacuerdo | I37: Totalmente de acuerdo | J37: Totalmente en desacuerdo | K37: Totalmente de acuerdo | L37: En desacuerdo | M37: Neutro | N37: Neutro | O37: En desacuerdo | P37: Neutro | Q37: Es una sistema pequeño, portátil y gráficamente muy fácil de entender todas las variables | R37: Siento que la norma es importante manejarla pero hay algo que no se tiene en cuenta y realmente no se tiene en cuenta a los verdaderos contaminantes peligrosos que existen y repercuten en la calidad del aire. Sería muy importante para la salud por que en la norma Colombiana se estabaoece unos contaminantes pero no se sabe qué tipos de contaminantes volátiles que no están en la norma que pueden estar afrentando la salud en las personas, animales | S37: La batería también debería ser portátil que funcione en cualquier lugar donde se ubique
A38: 46125.408 | B38: Jfaortega123@umariana.edu.co | C38: 21 | D38: Masculino | E38: Universidad (pregrado) | F38: Estudiante | G38: Totalmente en desacuerdo | H38: Totalmente en desacuerdo | I38: En desacuerdo | J38: En desacuerdo | K38: Totalmente en desacuerdo | L38: En desacuerdo | M38: En desacuerdo | N38: Totalmente en desacuerdo | O38: En desacuerdo | P38: Totalmente en desacuerdo | Q38: Tiene mucha innovación | R38: Hacerlo más portátil y que sea | S38: Que puedan acceder sin ser estudiante de la mariana
A39: 46125.409 | B39: mayeortega123@umariana.edu.co | C39: 21 | D39: Femenino | E39: Universidad (pregrado) | F39: Estudiante | G39: De acuerdo | H39: En desacuerdo | I39: En desacuerdo | J39: En desacuerdo | K39: De acuerdo | L39: En desacuerdo | M39: De acuerdo | N39: En desacuerdo | O39: Neutro | P39: Neutro | Q39: Es un producto muy bueno, innovador para estudiantes e investigadores, muy fácil de usar y que nos muestras gráficas fáciles de entender y también es muy importante que se puede descargar los reportes o datos de las fechas que se deseen. | R39: Me parece que sería importante que registre la ubicación y que en los reportes que se descargue también se puede indicar las gráficas. | S39: Me parece que esta muy fácil para acceder y usar, no tengo recomendaciones.
A40: 46125.409 | B40: emsagarreta123@umariana.edu.co | C40: 21 | D40: Masculino | E40: Secundaria | F40: Estudiante | G40: Totalmente en desacuerdo | H40: En desacuerdo | I40: Totalmente en desacuerdo | J40: En desacuerdo | K40: Totalmente en desacuerdo | L40: En desacuerdo | M40: Totalmente en desacuerdo | N40: En desacuerdo | O40: Totalmente en desacuerdo | P40: En desacuerdo | Q40: Es fácil de entender y fácil de manejar | R40: No se tiene en cuenta otros contaminantes más peligrosos y también de acuerdo a la concentración de estos, se debería dar una recomendación por ejemplo si está muy alto una recomendación como más ventilación o algo parecido | S40: Siento que es muy fácil de usar
...

Sheet 1
A1: Creo que me gustaría usar este sistema con frecuencia | B1: Frecuencia observada | C1: Porcentaje de la frecuencia observada
A2: Totalmente de acuerdo | B2: =COUNTIFS(Respuestas!$G$2:$G$42,"="&A2) -> 17 | C2: =B2/$B$7 -> 0.41463415
A3: De acuerdo | B3: =COUNTIFS(Respuestas!$G$2:$G$42,"="&A3) -> 12 | C3: =B3/$B$7 -> 0.29268293
A4: Neutro | B4: =COUNTIFS(Respuestas!$G$2:$G$42,"="&A4) -> 3 | C4: =B4/$B$7 -> 0.073170732
A5: Totalmente en desacuerdo | B5: =COUNTIFS(Respuestas!$G$2:$G$42,"="&A5) -> 8 | C5: =B5/$B$7 -> 0.19512195
A6: En desacuerdo | B6: =COUNTIFS(Respuestas!$G$2:$G$42,"="&A6) -> 1 | C6: =B6/$B$7 -> 0.024390244
A7: Total | B7: =SUM(B2:B6) -> 41 | C7: =SUM(C2:C6) -> 1
B9: de acuerdo | C9: =C2+C3 -> 0.70731707

Sheet 2
A1: [Encontré el sistema innecesariamente complejo] | B1: Frecuencia observada | C1: Porcentaje de la frecuencia observada
A2: Totalmente de acuerdo | B2: =COUNTIFS(Respuestas!$H$2:$H$42,"="&A2) -> 1 | C2: =B2/$B$7 -> 0.024390244
A3: De acuerdo | B3: =COUNTIFS(Respuestas!$H$2:$H$42,"="&A3) -> 1 | C3: =B3/$B$7 -> 0.024390244
A4: Neutro | B4: =COUNTIFS(Respuestas!$H$2:$H$42,"="&A4) -> 8 | C4: =B4/$B$7 -> 0.19512195
A5: Totalmente en desacuerdo | B5: =COUNTIFS(Respuestas!$H$2:$H$42,"="&A5) -> 13 | C5: =B5/$B$7 -> 0.31707317
A6: En desacuerdo | B6: =COUNTIFS(Respuestas!$H$2:$H$42,"="&A6) -> 18 | C6: =B6/$B$7 -> 0.43902439
A7: Total | B7: =SUM(B2:B6) -> 41 | C7: =SUM(C2:C6) -> 1

Sheet 3
A1: Pensé que el sistema era fácil de usar | B1: Frecuencia observada | C1: Porcentaje de la frecuencia observada
A2: Totalmente de acuerdo | B2: =COUNTIFS(Respuestas!$I$2:$I$42,"="&A2) -> 9 | C2: =B2/$B$7 -> 0.2195122
A3: De acuerdo | B3: =COUNTIFS(Respuestas!$I$2:$I$42,"="&A3) -> 6 | C3: =B3/$B$7 -> 0.14634146
A4: Neutro | B4: =COUNTIFS(Respuestas!$I$2:$I$42,"="&A4) -> 10 | C4: =B4/$B$7 -> 0.24390244
A5: Totalmente en desacuerdo | B5: =COUNTIFS(Respuestas!$I$2:$I$42,"="&A5) -> 9 | C5: =B5/$B$7 -> 0.2195122
A6: En desacuerdo | B6: =COUNTIFS(Respuestas!$I$2:$I$42,"="&A6) -> 7 | C6: =B6/$B$7 -> 0.17073171
A7: Total | B7: =SUM(B2:B6) -> 41 | C7: =SUM(C2:C6) -> 1
B9: de acuerdo | C9: =C2+C3 -> 0.36585366

Sheet 4
A1: Pensé que el sistema era fácil de usar | B1: Frecuencia observada | C1: Porcentaje de la frecuencia observada
A2: Totalmente de acuerdo | B2: =COUNTIFS(Respuestas!$J$2:$J$42,"="&A2) -> 2 | C2: =B2/$B$7 -> 0.048780488
A3: De acuerdo | B3: =COUNTIFS(Respuestas!$J$2:$J$42,"="&A3) -> 7 | C3: =B3/$B$7 -> 0.17073171
A4: Neutro | B4: =COUNTIFS(Respuestas!$J$2:$J$42,"="&A4) -> 3 | C4: =B4/$B$7 -> 0.073170732
A5: Totalmente en desacuerdo | B5: =COUNTIFS(Respuestas!$J$2:$J$42,"="&A5) -> 15 | C5: =B5/$B$7 -> 0.36585366
A6: En desacuerdo | B6: =COUNTIFS(Respuestas!$J$2:$J$42,"="&A6) -> 14 | C6: =B6/$B$7 -> 0.34146341
A7: Total | B7: =SUM(B2:B6) -> 41 | C7: =SUM(C2:C6) -> 1

Sheet 5
A1: Encontré que las diversas funciones del sistema estaban bien integradas | B1: Frecuencia observada | C1: Porcentaje de la frecuencia observada
A2: Totalmente de acuerdo | B2: =COUNTIFS(Respuestas!$K$2:$K$42,"="&A2) -> 20 | C2: =B2/$B$7 -> 0.48780488
A3: De acuerdo | B3: =COUNTIFS(Respuestas!$K$2:$K$42,"="&A3) -> 9 | C3: =B3/$B$7 -> 0.2195122
A4: Neutro | B4: =COUNTIFS(Respuestas!$K$2:$K$42,"="&A4) -> 4 | C4: =B4/$B$7 -> 0.097560976
A5: Totalmente en desacuerdo | B5: =COUNTIFS(Respuestas!$K$2:$K$42,"="&A5) -> 7 | C5: =B5/$B$7 -> 0.17073171
A6: En desacuerdo | B6: =COUNTIFS(Respuestas!$K$2:$K$42,"="&A6) -> 1 | C6: =B6/$B$7 -> 0.024390244
A7: Total | B7: =SUM(B2:B6) -> 41 | C7: =SUM(C2:C6) -> 1
B9: de acuerdo | C9: =C2+C3 -> 0.70731707

Sheet 6
A1: Pensé que había demasiada inconsistencia en este sistema | B1: Frecuencia observada | C1: Porcentaje de la frecuencia observada
A2: Totalmente de acuerdo | B2: =COUNTIFS(Respuestas!$L$2:$L$42,"="&A2) -> 1 | C2: =B2/$B$7 -> 0.024390244
A3: De acuerdo | B3: =COUNTIFS(Respuestas!$L$2:$L$42,"="&A3) -> 1 | C3: =B3/$B$7 -> 0.024390244
A4: Neutro | B4: =COUNTIFS(Respuestas!$L$2:$L$42,"="&A4) -> 6 | C4: =B4/$B$7 -> 0.14634146
A5: Totalmente en desacuerdo | B5: =COUNTIFS(Respuestas!$L$2:$L$42,"="&A5) -> 17 | C5: =B5/$B$7 -> 0.41463415
A6: En desacuerdo | B6: =COUNTIFS(Respuestas!$L$2:$L$42,"="&A6) -> 16 | C6: =B6/$B$7 -> 0.3902439
A7: Total | B7: =SUM(B2:B6) -> 41 | C7: =SUM(C2:C6) -> 1

Sheet 7
A1: Considero que la mayoría de las personas aprenderían a usar este sistema muy rápidamente | B1: Frecuencia observada | C1: Porcentaje de la frecuencia observada
A2: Totalmente de acuerdo | B2: =COUNTIFS(Respuestas!$M$2:$M$42,"="&A2) -> 18 | C2: =B2/$B$7 -> 0.43902439
A3: De acuerdo | B3: =COUNTIFS(Respuestas!$M$2:$M$42,"="&A3) -> 11 | C3: =B3/$B$7 -> 0.26829268
A4: Neutro | B4: =COUNTIFS(Respuestas!$M$2:$M$42,"="&A4) -> 4 | C4: =B4/$B$7 -> 0.097560976
A5: Totalmente en desacuerdo | B5: =COUNTIFS(Respuestas!$M$2:$M$42,"="&A5) -> 7 | C5: =B5/$B$7 -> 0.17073171
A6: En desacuerdo | B6: =COUNTIFS(Respuestas!$M$2:$M$42,"="&A6) -> 1 | C6: =B6/$B$7 -> 0.024390244
A7: Total | B7: =SUM(B2:B6) -> 41 | C7: =SUM(C2:C6) -> 1
B9: de acuerdo | C9: =C2+C3 -> 0.70731707

Sheet 8
A1: Encontré el sistema muy complicado de usar | B1: Frecuencia observada | C1: Porcentaje de la frecuencia observada
A2: Totalmente de acuerdo | B2: =COUNTIFS(Respuestas!$N$2:$N$42,"="&A2) -> 1 | C2: =B2/$B$7 -> 0.024390244
A3: De acuerdo | B3: =COUNTIFS(Respuestas!$N$2:$N$42,"="&A3) -> 2 | C3: =B3/$B$7 -> 0.048780488
A4: Neutro | B4: =COUNTIFS(Respuestas!$N$2:$N$42,"="&A4) -> 4 | C4: =B4/$B$7 -> 0.097560976
A5: Totalmente en desacuerdo | B5: =COUNTIFS(Respuestas!$N$2:$N$42,"="&A5) -> 23 | C5: =B5/$B$7 -> 0.56097561
A6: En desacuerdo | B6: =COUNTIFS(Respuestas!$N$2:$N$42,"="&A6) -> 11 | C6: =B6/$B$7 -> 0.26829268
A7: Total | B7: =SUM(B2:B6) -> 41 | C7: =SUM(C2:C6) -> 1

Sheet 9
A1: Me sentí muy seguro(a) usando el sistema | B1: Frecuencia observada | C1: Porcentaje de la frecuencia observada
A2: Totalmente de acuerdo | B2: =COUNTIFS(Respuestas!$O$2:$O$42,"="&A2) -> 17 | C2: =B2/$B$7 -> 0.41463415
A3: De acuerdo | B3: =COUNTIFS(Respuestas!$O$2:$O$42,"="&A3) -> 8 | C3: =B3/$B$7 -> 0.19512195
A4: Neutro | B4: =COUNTIFS(Respuestas!$O$2:$O$42,"="&A4) -> 6 | C4: =B4/$B$7 -> 0.14634146
A5: Totalmente en desacuerdo | B5: =COUNTIFS(Respuestas!$O$2:$O$42,"="&A5) -> 6 | C5: =B5/$B$7 -> 0.14634146
A6: En desacuerdo | B6: =COUNTIFS(Respuestas!$O$2:$O$42,"="&A6) -> 4 | C6: =B6/$B$7 -> 0.097560976
A7: Total | B7: =SUM(B2:B6) -> 41 | C7: =SUM(C2:C6) -> 1
B9: de acuerdo | C9: =C2+C3 -> 0.6097561

Sheet 10
A1: Necesité aprender muchas cosas antes de poder empezar a usar este sistema | B1: Frecuencia observada | C1: Porcentaje de la frecuencia observada
A2: Totalmente de acuerdo | B2: =COUNTIFS(Respuestas!$P$2:$P$42,"="&A2) -> 1 | C2: =B2/$B$7 -> 0.024390244
A3: De acuerdo | B3: =COUNTIFS(Respuestas!$P$2:$P$42,"="&A3) -> 4 | C3: =B3/$B$7 -> 0.097560976
A4: Neutro | B4: =COUNTIFS(Respuestas!$P$2:$P$42,"="&A4) -> 10 | C4: =B4/$B$7 -> 0.24390244
A5: Totalmente en desacuerdo | B5: =COUNTIFS(Respuestas!$P$2:$P$42,"="&A5) -> 18 | C5: =B5/$B$7 -> 0.43902439
A6: En desacuerdo | B6: =COUNTIFS(Respuestas!$P$2:$P$42,"="&A6) -> 8 | C6: =B6/$B$7 -> 0.19512195
A7: Total | B7: =SUM(B2:B6) -> 41 | C7: =SUM(C2:C6) -> 1

Sheet Edad
A1: Edad | B1: Frecuencia observada | C1: Porcentaje de la frecuencia observada
A2: 17 | B2: =COUNTIFS(Respuestas!$C$2:$C$42,"="&A2) -> 1 | C2: =B2/$B$19 -> 0.024390244
A3: 18 | B3: =COUNTIFS(Respuestas!$C$2:$C$42,"="&A3) -> 3 | C3: =B3/$B$19 -> 0.073170732
A4: 19 | B4: =COUNTIFS(Respuestas!$C$2:$C$42,"="&A4) -> 4 | C4: =B4/$B$19 -> 0.097560976
A5: 20 | B5: =COUNTIFS(Respuestas!$C$2:$C$42,"="&A5) -> 5 | C5: =B5/$B$19 -> 0.12195122
A6: 21 | B6: =COUNTIFS(Respuestas!$C$2:$C$42,"="&A6) -> 8 | C6: =B6/$B$19 -> 0.19512195
A7: 22 | B7: =COUNTIFS(Respuestas!$C$2:$C$42,"="&A7) -> 2 | C7: =B7/$B$19 -> 0.048780488
A8: 23 | B8: =COUNTIFS(Respuestas!$C$2:$C$42,"="&A8) -> 4 | C8: =B8/$B$19 -> 0.097560976
A9: 25 | B9: =COUNTIFS(Respuestas!$C$2:$C$42,"="&A9) -> 3 | C9: =B9/$B$19 -> 0.073170732
A10: 27 | B10: =COUNTIFS(Respuestas!$C$2:$C$42,"="&A10) -> 1 | C10: =B10/$B$19 -> 0.024390244
A11: 28 | B11: =COUNTIFS(Respuestas!$C$2:$C$42,"="&A11) -> 1 | C11: =B11/$B$19 -> 0.024390244
A12: 35 | B12: =COUNTIFS(Respuestas!$C$2:$C$42,"="&A12) -> 1 | C12: =B12/$B$19 -> 0.024390244
A13: 38 | B13: =COUNTIFS(Respuestas!$C$2:$C$42,"="&A13) -> 2 | C13: =B13/$B$19 -> 0.048780488
... A18: 53 | B18: =COUNTIFS(Respuestas!$C$2:$C$42,"="&A18) -> 1 | C18: =B18/$B$19 -> 0.024390244
A19: total | B19: =SUM(B2:B18) -> 41 | C19: =SUM(C2:C18) -> 1

Sheet Nivel educativo
A1: Nivel educativo | B1: Frecuencia observada | C1: Porcentaje de la frecuencia observada
A2: Posgrado | B2: =COUNTIFS(Respuestas!$E$2:$E$42,"="&A2) -> 10 | C2: =B2/$B$6 -> 0.24390244
A3: Universidad (pregrado) | B3: =COUNTIFS(Respuestas!$E$2:$E$42,"="&A3) -> 27 | C3: =B3/$B$6 -> 0.65853659
A4: Secundaria | B4: =COUNTIFS(Respuestas!$E$2:$E$42,"="&A4) -> 3 | C4: =B4/$B$6 -> 0.073170732
A5: Educación técnica o tecnológica | B5: =COUNTIFS(Respuestas!$E$2:$E$42,"="&A5) -> 1 | C5: =B5/$B$6 -> 0.024390244
A6: total | B6: =SUM(B2:B5) -> 41 | C6: =SUM(C2:C5) -> 1

Sheet Genero
A1: Género | B1: Frecuencia observada | C1: Porcentaje de la frecuencia observada
A2: Masculino | B2: =COUNTIFS(Respuestas!$D$2:$D$42,"="&A2) -> 15 | C2: =B2/$B$4 -> 0.36585366
A3: Femenino | B3: =COUNTIFS(Respuestas!$D$2:$D$42,"="&A3) -> 26 | C3: =B3/$B$4 -> 0.63414634
A4: total | B4: =SUM(B2:B3) -> 41 | C4: =SUM(C2:C3) -> 1
